
0 static files copied to '/home/l/loshga99/loshga99.beget.tech/backend/staticfiles', 162 unmodified, 466 post-processed.

0 static files copied to '/home/l/loshga99/loshga99.beget.tech/backend/staticfiles', 162 unmodified, 423 post-processed.
Traceback (most recent call last):
Traceback (most recent call last):
  File "/home/l/loshga99/loshga99.beget.tech/backend/manage.py", line 12, in main
  File "/home/l/loshga99/loshga99.beget.tech/backend/manage.py", line 12, in main
        from django.core.management import execute_from_command_linefrom django.core.management import execute_from_command_line

ModuleNotFoundErrorModuleNotFoundError: : No module named 'django'No module named 'django'



The above exception was the direct cause of the following exception:
The above exception was the direct cause of the following exception:


Traceback (most recent call last):
Traceback (most recent call last):
  File "/home/l/loshga99/loshga99.beget.tech/backend/manage.py", line 23, in <module>
  File "/home/l/loshga99/loshga99.beget.tech/backend/manage.py", line 23, in <module>
        main()main()

  File "/home/l/loshga99/loshga99.beget.tech/backend/manage.py", line 14, in main
  File "/home/l/loshga99/loshga99.beget.tech/backend/manage.py", line 14, in main
        raise ImportError(raise ImportError(

ImportErrorImportError: : Couldn't import Django. Are you sure it's installed and available on your PYTHONPATH environment variable? Did you forget to activate a virtual environment?Couldn't import Django. Are you sure it's installed and available on your PYTHONPATH environment variable? Did you forget to activate a virtual environment?

[CommandError: Unable to serialize database: 'latin-1' codec can't encode characters in position 0-5: ordinal not in range(256)
CommandError: Unable to serialize database: 'latin-1' codec can't encode characters in position 0-5: ordinal not in range(256)
CommandError: Unable to serialize database: 'latin-1' codec can't encode characters in position 0-5: ordinal not in range(256)
CommandError: Unable to serialize database: 'latin-1' codec can't encode characters in position 0-5: ordinal not in range(256)
[CommandError: Unable to serialize database: 'latin-1' codec can't encode characters in position 0-5: ordinal not in range(256)
CommandError: Unable to serialize database: 'latin-1' codec can't encode characters in position 0-5: ordinal not in range(256)
[CommandError: Unable to serialize database: 'latin-1' codec can't encode characters in position 0-5: ordinal not in range(256)
CommandError: Unable to serialize database: 'latin-1' codec can't encode characters in position 0-5: ordinal not in range(256)
[CommandError: Unable to serialize database: 'latin-1' codec can't encode characters in position 0-5: ordinal not in range(256)
CommandError: Unable to serialize database: 'latin-1' codec can't encode characters in position 0-5: ordinal not in range(256)
Traceback (most recent call last):
Traceback (most recent call last):
  File "/home/l/loshga99/loshga99.beget.tech/backend/manage.py", line 23, in <module>
  File "/home/l/loshga99/loshga99.beget.tech/backend/manage.py", line 23, in <module>
        main()main()

  File "/home/l/loshga99/loshga99.beget.tech/backend/manage.py", line 19, in main
  File "/home/l/loshga99/loshga99.beget.tech/backend/manage.py", line 19, in main
        execute_from_command_line(sys.argv)execute_from_command_line(sys.argv)

  File "/home/l/loshga99/myenv/lib/python3.12/site-packages/django/core/management/__init__.py", line 442, in execute_from_command_line
  File "/home/l/loshga99/myenv/lib/python3.12/site-packages/django/core/management/__init__.py", line 442, in execute_from_command_line
        utility.execute()utility.execute()

  File "/home/l/loshga99/myenv/lib/python3.12/site-packages/django/core/management/__init__.py", line 436, in execute
  File "/home/l/loshga99/myenv/lib/python3.12/site-packages/django/core/management/__init__.py", line 436, in execute
        self.fetch_command(subcommand).run_from_argv(self.argv)self.fetch_command(subcommand).run_from_argv(self.argv)

  File "/home/l/loshga99/myenv/lib/python3.12/site-packages/django/core/management/base.py", line 416, in run_from_argv
  File "/home/l/loshga99/myenv/lib/python3.12/site-packages/django/core/management/base.py", line 416, in run_from_argv
        self.execute(*args, **cmd_options)self.execute(*args, **cmd_options)

  File "/home/l/loshga99/myenv/lib/python3.12/site-packages/django/core/management/base.py", line 457, in execute
  File "/home/l/loshga99/myenv/lib/python3.12/site-packages/django/core/management/base.py", line 457, in execute
        self.check(**check_kwargs)self.check(**check_kwargs)

  File "/home/l/loshga99/myenv/lib/python3.12/site-packages/django/core/management/base.py", line 492, in check
  File "/home/l/loshga99/myenv/lib/python3.12/site-packages/django/core/management/base.py", line 492, in check
        all_issues = checks.run_checks(all_issues = checks.run_checks(

                                  ^^^^^^^^^^^^^^^^^^^^^^^^^^^^^^^^^^^^

  File "/home/l/loshga99/myenv/lib/python3.12/site-packages/django/core/checks/registry.py", line 89, in run_checks
  File "/home/l/loshga99/myenv/lib/python3.12/site-packages/django/core/checks/registry.py", line 89, in run_checks
        new_errors = check(app_configs=app_configs, databases=databases)new_errors = check(app_configs=app_configs, databases=databases)

                                  ^^^^^^^^^^^^^^^^^^^^^^^^^^^^^^^^^^^^^^^^^^^^^^^^^^^^^^^^^^^^^^^^^^^^^^^^^^^^^^^^^^^^^^^^^^^^^^^^^^^^^^

  File "/home/l/loshga99/myenv/lib/python3.12/site-packages/django/core/checks/database.py", line 13, in check_database_backends
  File "/home/l/loshga99/myenv/lib/python3.12/site-packages/django/core/checks/database.py", line 13, in check_database_backends
        issues.extend(conn.validation.check(**kwargs))issues.extend(conn.validation.check(**kwargs))

                                    ^^^^^^^^^^^^^^^^^^^^^^^^^^^^^^^^^^^^^^^^^^^^^^^^^^^^^^^^^^^^^^

  File "/home/l/loshga99/myenv/lib/python3.12/site-packages/django/db/backends/mysql/validation.py", line 9, in check
  File "/home/l/loshga99/myenv/lib/python3.12/site-packages/django/db/backends/mysql/validation.py", line 9, in check
        issues.extend(self._check_sql_mode(**kwargs))issues.extend(self._check_sql_mode(**kwargs))

                                    ^^^^^^^^^^^^^^^^^^^^^^^^^^^^^^^^^^^^^^^^^^^^^^^^^^^^^^^^^^^^

  File "/home/l/loshga99/myenv/lib/python3.12/site-packages/django/db/backends/mysql/validation.py", line 14, in _check_sql_mode
  File "/home/l/loshga99/myenv/lib/python3.12/site-packages/django/db/backends/mysql/validation.py", line 14, in _check_sql_mode
        self.connection.sql_mode & {"STRICT_TRANS_TABLES", "STRICT_ALL_TABLES"}self.connection.sql_mode & {"STRICT_TRANS_TABLES", "STRICT_ALL_TABLES"}

        ^^^^^^^^^^^^^^^^^^^^^^^^^^^^^^^^^^^^^^^^^^^^^^^^

  File "/home/l/loshga99/myenv/lib/python3.12/site-packages/django/utils/functional.py", line 47, in __get__
  File "/home/l/loshga99/myenv/lib/python3.12/site-packages/django/utils/functional.py", line 47, in __get__
        res = instance.__dict__[self.name] = self.func(instance)res = instance.__dict__[self.name] = self.func(instance)

                                                                                  ^^^^^^^^^^^^^^^^^^^^^^^^^^^^^^^^^^^^^^

  File "/home/l/loshga99/myenv/lib/python3.12/site-packages/django/db/backends/mysql/base.py", line 448, in sql_mode
  File "/home/l/loshga99/myenv/lib/python3.12/site-packages/django/db/backends/mysql/base.py", line 448, in sql_mode
        sql_mode = self.mysql_server_data["sql_mode"]sql_mode = self.mysql_server_data["sql_mode"]

                              ^^^^^^^^^^^^^^^^^^^^^^^^^^^^^^^^^^^^^^^^^^^^

  File "/home/l/loshga99/myenv/lib/python3.12/site-packages/django/utils/functional.py", line 47, in __get__
  File "/home/l/loshga99/myenv/lib/python3.12/site-packages/django/utils/functional.py", line 47, in __get__
        res = instance.__dict__[self.name] = self.func(instance)res = instance.__dict__[self.name] = self.func(instance)

                                                                                  ^^^^^^^^^^^^^^^^^^^^^^^^^^^^^^^^^^^^^^

  File "/home/l/loshga99/myenv/lib/python3.12/site-packages/django/db/backends/mysql/base.py", line 404, in mysql_server_data
  File "/home/l/loshga99/myenv/lib/python3.12/site-packages/django/db/backends/mysql/base.py", line 404, in mysql_server_data
        with self.temporary_connection() as cursor:with self.temporary_connection() as cursor:

  File "/home/l/loshga99/.local/lib/python3.12/contextlib.py", line 137, in __enter__
  File "/home/l/loshga99/.local/lib/python3.12/contextlib.py", line 137, in __enter__
        return next(self.gen)return next(self.gen)

                      ^^^^^^^^^^^^^^^^^^^^^^^^^^^^

  File "/home/l/loshga99/myenv/lib/python3.12/site-packages/django/db/backends/base/base.py", line 695, in temporary_connection
  File "/home/l/loshga99/myenv/lib/python3.12/site-packages/django/db/backends/base/base.py", line 695, in temporary_connection
        with self.cursor() as cursor:with self.cursor() as cursor:

                  ^^^^^^^^^^^^^^^^^^^^^^^^^^

  File "/home/l/loshga99/myenv/lib/python3.12/site-packages/django/utils/asyncio.py", line 26, in inner
  File "/home/l/loshga99/myenv/lib/python3.12/site-packages/django/utils/asyncio.py", line 26, in inner
        return func(*args, **kwargs)return func(*args, **kwargs)

                      ^^^^^^^^^^^^^^^^^^^^^^^^^^^^^^^^^^^^^^^^^^

  File "/home/l/loshga99/myenv/lib/python3.12/site-packages/django/db/backends/base/base.py", line 320, in cursor
  File "/home/l/loshga99/myenv/lib/python3.12/site-packages/django/db/backends/base/base.py", line 320, in cursor
        return self._cursor()return self._cursor()

                      ^^^^^^^^^^^^^^^^^^^^^^^^^^^^

  File "/home/l/loshga99/myenv/lib/python3.12/site-packages/django/db/backends/base/base.py", line 296, in _cursor
  File "/home/l/loshga99/myenv/lib/python3.12/site-packages/django/db/backends/base/base.py", line 296, in _cursor
        self.ensure_connection()self.ensure_connection()

  File "/home/l/loshga99/myenv/lib/python3.12/site-packages/django/utils/asyncio.py", line 26, in inner
  File "/home/l/loshga99/myenv/lib/python3.12/site-packages/django/utils/asyncio.py", line 26, in inner
        return func(*args, **kwargs)return func(*args, **kwargs)

                      ^^^^^^^^^^^^^^^^^^^^^^^^^^^^^^^^^^^^^^^^^^

  File "/home/l/loshga99/myenv/lib/python3.12/site-packages/django/db/backends/base/base.py", line 279, in ensure_connection
  File "/home/l/loshga99/myenv/lib/python3.12/site-packages/django/db/backends/base/base.py", line 279, in ensure_connection
        self.connect()self.connect()

  File "/home/l/loshga99/myenv/lib/python3.12/site-packages/django/utils/asyncio.py", line 26, in inner
  File "/home/l/loshga99/myenv/lib/python3.12/site-packages/django/utils/asyncio.py", line 26, in inner
        return func(*args, **kwargs)return func(*args, **kwargs)

                      ^^^^^^^^^^^^^^^^^^^^^^^^^^^^^^^^^^^^^^^^^^

  File "/home/l/loshga99/myenv/lib/python3.12/site-packages/django/db/backends/base/base.py", line 258, in connect
  File "/home/l/loshga99/myenv/lib/python3.12/site-packages/django/db/backends/base/base.py", line 258, in connect
        self.init_connection_state()self.init_connection_state()

  File "/home/l/loshga99/myenv/lib/python3.12/site-packages/django/db/backends/mysql/base.py", line 266, in init_connection_state
  File "/home/l/loshga99/myenv/lib/python3.12/site-packages/django/db/backends/mysql/base.py", line 266, in init_connection_state
        super().init_connection_state()super().init_connection_state()

  File "/home/l/loshga99/myenv/lib/python3.12/site-packages/django/db/backends/base/base.py", line 225, in init_connection_state
  File "/home/l/loshga99/myenv/lib/python3.12/site-packages/django/db/backends/base/base.py", line 225, in init_connection_state
        self.check_database_version_supported()self.check_database_version_supported()

  File "/home/l/loshga99/myenv/lib/python3.12/site-packages/django/db/backends/base/base.py", line 201, in check_database_version_supported
  File "/home/l/loshga99/myenv/lib/python3.12/site-packages/django/db/backends/base/base.py", line 201, in check_database_version_supported
        raise NotSupportedError(raise NotSupportedError(

django.db.utilsdjango.db.utils..NotSupportedErrorNotSupportedError: : MySQL 8.0.11 or later is required (found 5.7.21).MySQL 8.0.11 or later is required (found 5.7.21).

[CommandError: Unable to serialize database: (1146, "Table 'loshga99_design.django_admin_log' doesn't exist")
CommandError: Unable to serialize database: (1146, "Table 'loshga99_design.django_admin_log' doesn't exist")
System check identified some issues:

WARNINGS:
?: (mysql.W002) MySQL Strict Mode is not set for database connection 'default'
	HINT: MySQL's Strict Mode fixes many data integrity problems in MySQL, such as data truncation upon insertion, by escalating warnings into errors. It is strongly recommended you activate it. See: https://docs.djangoproject.com/en/5.2/ref/databases/#mysql-sql-mode
System check identified some issues:

WARNINGS:
?: (mysql.W002) MySQL Strict Mode is not set for database connection 'default'
	HINT: MySQL's Strict Mode fixes many data integrity problems in MySQL, such as data truncation upon insertion, by escalating warnings into errors. It is strongly recommended you activate it. See: https://docs.djangoproject.com/en/5.2/ref/databases/#mysql-sql-mode
Operations to perform:
  Apply all migrations: admin, auth, backend_api, contenttypes, sessions
Running migrations:
  Applying contenttypes.0001_initial... OK
  Applying auth.0001_initial... OK
  Applying admin.0001_initial... OK
  Applying admin.0002_logentry_remove_auto_add... OK
  Applying admin.0003_logentry_add_action_flag_choices... OK
  Applying contenttypes.0002_remove_content_type_name... OK
  Applying auth.0002_alter_permission_name_max_length... OK
  Applying auth.0003_alter_user_email_max_length... OK
  Applying auth.0004_alter_user_username_opts... OK
  Applying auth.0005_alter_user_last_login_null... OK
  Applying auth.0006_require_contenttypes_0002... OK
  Applying auth.0007_alter_validators_add_error_messages... OK
  Applying auth.0008_alter_user_username_max_length... OK
  Applying auth.0009_alter_user_last_name_max_length... OK
  Applying auth.0010_alter_group_name_max_length... OK
  Applying auth.0011_update_proxy_permissions... OK
  Applying auth.0012_alter_user_first_name_max_length... OK
  Applying backend_api.0001_initial... OK
  Applying backend_api.0002_alter_testimonial_image... OK
  Applying backend_api.0003_project_projectimage_projectimagepanorama... OK
  Applying sessions.0001_initial... OK
order@alldesignkhv.ru (147369fgH+)
Username (leave blank to use 'loshga99'): Email address: Superuser created successfully.
Traceback (most recent call last):
Traceback (most recent call last):
  File "C:\Codes\GitHub\alldesign_website\backend\manage.py", line 12, in main
  File "C:\Codes\GitHub\alldesign_website\backend\manage.py", line 12, in main
        from django.core.management import execute_from_command_linefrom django.core.management import execute_from_command_line

ModuleNotFoundErrorModuleNotFoundError: : No module named 'django'No module named 'django'



The above exception was the direct cause of the following exception:
The above exception was the direct cause of the following exception:


Traceback (most recent call last):
Traceback (most recent call last):
  File "C:\Codes\GitHub\alldesign_website\backend\manage.py", line 23, in <module>
  File "C:\Codes\GitHub\alldesign_website\backend\manage.py", line 23, in <module>
        main()main()

  File "C:\Codes\GitHub\alldesign_website\backend\manage.py", line 14, in main
  File "C:\Codes\GitHub\alldesign_website\backend\manage.py", line 14, in main
        raise ImportError(raise ImportError(

ImportErrorImportError: : Couldn't import Django. Are you sure it's installed and available on your PYTHONPATH environment variable? Did you forget to activate a virtual environment?Couldn't import Django. Are you sure it's installed and available on your PYTHONPATH environment variable? Did you forget to activate a virtual environment?

Traceback (most recent call last):
Traceback (most recent call last):
  File "C:\Codes\GitHub\alldesign_website\backend\manage.py", line 23, in <module>
  File "C:\Codes\GitHub\alldesign_website\backend\manage.py", line 23, in <module>
        main()main()

  File "C:\Codes\GitHub\alldesign_website\backend\manage.py", line 19, in main
  File "C:\Codes\GitHub\alldesign_website\backend\manage.py", line 19, in main
        execute_from_command_line(sys.argv)execute_from_command_line(sys.argv)

  File "C:\Users\DeogSeon\AppData\Local\Packages\PythonSoftwareFoundation.Python.3.12_qbz5n2kfra8p0\LocalCache\local-packages\Python312\site-packages\django\core\management\__init__.py", line 442, in execute_from_command_line
  File "C:\Users\DeogSeon\AppData\Local\Packages\PythonSoftwareFoundation.Python.3.12_qbz5n2kfra8p0\LocalCache\local-packages\Python312\site-packages\django\core\management\__init__.py", line 442, in execute_from_command_line
        utility.execute()utility.execute()

  File "C:\Users\DeogSeon\AppData\Local\Packages\PythonSoftwareFoundation.Python.3.12_qbz5n2kfra8p0\LocalCache\local-packages\Python312\site-packages\django\core\management\__init__.py", line 436, in execute
  File "C:\Users\DeogSeon\AppData\Local\Packages\PythonSoftwareFoundation.Python.3.12_qbz5n2kfra8p0\LocalCache\local-packages\Python312\site-packages\django\core\management\__init__.py", line 436, in execute
        self.fetch_command(subcommand).run_from_argv(self.argv)self.fetch_command(subcommand).run_from_argv(self.argv)

  File "C:\Users\DeogSeon\AppData\Local\Packages\PythonSoftwareFoundation.Python.3.12_qbz5n2kfra8p0\LocalCache\local-packages\Python312\site-packages\django\core\management\base.py", line 408, in run_from_argv
  File "C:\Users\DeogSeon\AppData\Local\Packages\PythonSoftwareFoundation.Python.3.12_qbz5n2kfra8p0\LocalCache\local-packages\Python312\site-packages\django\core\management\base.py", line 408, in run_from_argv
        parser = self.create_parser(argv[0], argv[1])parser = self.create_parser(argv[0], argv[1])

                          ^^^^^^^^^^^^^^^^^^^^^^^^^^^^^^^^^^^^^^^^^^^^^^^^^^^^^^^^^^^^^^^^^^^^^^^^

  File "C:\Users\DeogSeon\AppData\Local\Packages\PythonSoftwareFoundation.Python.3.12_qbz5n2kfra8p0\LocalCache\local-packages\Python312\site-packages\django\core\management\base.py", line 371, in create_parser
  File "C:\Users\DeogSeon\AppData\Local\Packages\PythonSoftwareFoundation.Python.3.12_qbz5n2kfra8p0\LocalCache\local-packages\Python312\site-packages\django\core\management\base.py", line 371, in create_parser
        self.add_arguments(parser)self.add_arguments(parser)

  File "C:\Users\DeogSeon\AppData\Local\Packages\PythonSoftwareFoundation.Python.3.12_qbz5n2kfra8p0\LocalCache\local-packages\Python312\site-packages\django\core\management\commands\migrate.py", line 45, in add_arguments
  File "C:\Users\DeogSeon\AppData\Local\Packages\PythonSoftwareFoundation.Python.3.12_qbz5n2kfra8p0\LocalCache\local-packages\Python312\site-packages\django\core\management\commands\migrate.py", line 45, in add_arguments
        choices=tuple(connections),choices=tuple(connections),

                        ^^^^^^^^^^^^^^^^^^^^^^^^^^^^^^^^^^^^

  File "C:\Users\DeogSeon\AppData\Local\Packages\PythonSoftwareFoundation.Python.3.12_qbz5n2kfra8p0\LocalCache\local-packages\Python312\site-packages\django\utils\connection.py", line 73, in __iter__
  File "C:\Users\DeogSeon\AppData\Local\Packages\PythonSoftwareFoundation.Python.3.12_qbz5n2kfra8p0\LocalCache\local-packages\Python312\site-packages\django\utils\connection.py", line 73, in __iter__
        return iter(self.settings)return iter(self.settings)

                                ^^^^^^^^^^^^^^^^^^^^^^^^^^

  File "C:\Users\DeogSeon\AppData\Local\Packages\PythonSoftwareFoundation.Python.3.12_qbz5n2kfra8p0\LocalCache\local-packages\Python312\site-packages\django\utils\functional.py", line 47, in __get__
  File "C:\Users\DeogSeon\AppData\Local\Packages\PythonSoftwareFoundation.Python.3.12_qbz5n2kfra8p0\LocalCache\local-packages\Python312\site-packages\django\utils\functional.py", line 47, in __get__
        res = instance.__dict__[self.name] = self.func(instance)res = instance.__dict__[self.name] = self.func(instance)

                                                                                  ^^^^^^^^^^^^^^^^^^^^^^^^^^^^^^^^^^^^^^

  File "C:\Users\DeogSeon\AppData\Local\Packages\PythonSoftwareFoundation.Python.3.12_qbz5n2kfra8p0\LocalCache\local-packages\Python312\site-packages\django\utils\connection.py", line 45, in settings
  File "C:\Users\DeogSeon\AppData\Local\Packages\PythonSoftwareFoundation.Python.3.12_qbz5n2kfra8p0\LocalCache\local-packages\Python312\site-packages\django\utils\connection.py", line 45, in settings
        self._settings = self.configure_settings(self._settings)self._settings = self.configure_settings(self._settings)

                                          ^^^^^^^^^^^^^^^^^^^^^^^^^^^^^^^^^^^^^^^^^^^^^^^^^^^^^^^^^^^^^^^^^^^^^^^^^^^^^^

  File "C:\Users\DeogSeon\AppData\Local\Packages\PythonSoftwareFoundation.Python.3.12_qbz5n2kfra8p0\LocalCache\local-packages\Python312\site-packages\django\db\utils.py", line 148, in configure_settings
  File "C:\Users\DeogSeon\AppData\Local\Packages\PythonSoftwareFoundation.Python.3.12_qbz5n2kfra8p0\LocalCache\local-packages\Python312\site-packages\django\db\utils.py", line 148, in configure_settings
        databases = super().configure_settings(databases)databases = super().configure_settings(databases)

                                ^^^^^^^^^^^^^^^^^^^^^^^^^^^^^^^^^^^^^^^^^^^^^^^^^^^^^^^^^^^^^^^^^^^^^^^^^^

  File "C:\Users\DeogSeon\AppData\Local\Packages\PythonSoftwareFoundation.Python.3.12_qbz5n2kfra8p0\LocalCache\local-packages\Python312\site-packages\django\utils\connection.py", line 50, in configure_settings
  File "C:\Users\DeogSeon\AppData\Local\Packages\PythonSoftwareFoundation.Python.3.12_qbz5n2kfra8p0\LocalCache\local-packages\Python312\site-packages\django\utils\connection.py", line 50, in configure_settings
        settings = getattr(django_settings, self.settings_name)settings = getattr(django_settings, self.settings_name)

                              ^^^^^^^^^^^^^^^^^^^^^^^^^^^^^^^^^^^^^^^^^^^^^^^^^^^^^^^^^^^^^^^^^^^^^^^^^^^^^^^^^^^^^^^^

  File "C:\Users\DeogSeon\AppData\Local\Packages\PythonSoftwareFoundation.Python.3.12_qbz5n2kfra8p0\LocalCache\local-packages\Python312\site-packages\django\conf\__init__.py", line 81, in __getattr__
  File "C:\Users\DeogSeon\AppData\Local\Packages\PythonSoftwareFoundation.Python.3.12_qbz5n2kfra8p0\LocalCache\local-packages\Python312\site-packages\django\conf\__init__.py", line 81, in __getattr__
        self._setup(name)self._setup(name)

  File "C:\Users\DeogSeon\AppData\Local\Packages\PythonSoftwareFoundation.Python.3.12_qbz5n2kfra8p0\LocalCache\local-packages\Python312\site-packages\django\conf\__init__.py", line 68, in _setup
  File "C:\Users\DeogSeon\AppData\Local\Packages\PythonSoftwareFoundation.Python.3.12_qbz5n2kfra8p0\LocalCache\local-packages\Python312\site-packages\django\conf\__init__.py", line 68, in _setup
        self._wrapped = Settings(settings_module)self._wrapped = Settings(settings_module)

                                        ^^^^^^^^^^^^^^^^^^^^^^^^^^^^^^^^^^^^^^^^^^^^^^^^^^

  File "C:\Users\DeogSeon\AppData\Local\Packages\PythonSoftwareFoundation.Python.3.12_qbz5n2kfra8p0\LocalCache\local-packages\Python312\site-packages\django\conf\__init__.py", line 166, in __init__
  File "C:\Users\DeogSeon\AppData\Local\Packages\PythonSoftwareFoundation.Python.3.12_qbz5n2kfra8p0\LocalCache\local-packages\Python312\site-packages\django\conf\__init__.py", line 166, in __init__
        mod = importlib.import_module(self.SETTINGS_MODULE)mod = importlib.import_module(self.SETTINGS_MODULE)

                    ^^^^^^^^^^^^^^^^^^^^^^^^^^^^^^^^^^^^^^^^^^^^^^^^^^^^^^^^^^^^^^^^^^^^^^^^^^^^^^^^^^^^^^^^^^

  File "C:\Program Files\WindowsApps\PythonSoftwareFoundation.Python.3.12_3.12.2800.0_x64__qbz5n2kfra8p0\Lib\importlib\__init__.py", line 90, in import_module
  File "C:\Program Files\WindowsApps\PythonSoftwareFoundation.Python.3.12_3.12.2800.0_x64__qbz5n2kfra8p0\Lib\importlib\__init__.py", line 90, in import_module
        return _bootstrap._gcd_import(name[level:], package, level)return _bootstrap._gcd_import(name[level:], package, level)

                      ^^^^^^^^^^^^^^^^^^^^^^^^^^^^^^^^^^^^^^^^^^^^^^^^^^^^^^^^^^^^^^^^^^^^^^^^^^^^^^^^^^^^^^^^^^^^^^^^^^^^^^^^

  File "<frozen importlib._bootstrap>", line 1387, in _gcd_import
  File "<frozen importlib._bootstrap>", line 1387, in _gcd_import
  File "<frozen importlib._bootstrap>", line 1360, in _find_and_load
  File "<frozen importlib._bootstrap>", line 1360, in _find_and_load
  File "<frozen importlib._bootstrap>", line 1331, in _find_and_load_unlocked
  File "<frozen importlib._bootstrap>", line 1331, in _find_and_load_unlocked
  File "<frozen importlib._bootstrap>", line 935, in _load_unlocked
  File "<frozen importlib._bootstrap>", line 935, in _load_unlocked
  File "<frozen importlib._bootstrap_external>", line 999, in exec_module
  File "<frozen importlib._bootstrap_external>", line 999, in exec_module
  File "<frozen importlib._bootstrap>", line 488, in _call_with_frames_removed
  File "<frozen importlib._bootstrap>", line 488, in _call_with_frames_removed
  File "C:\Codes\GitHub\alldesign_website\backend\backend\settings.py", line 3, in <module>
  File "C:\Codes\GitHub\alldesign_website\backend\backend\settings.py", line 3, in <module>
        from dotenv import load_dotenvfrom dotenv import load_dotenv

ModuleNotFoundErrorModuleNotFoundError: : No module named 'dotenv'No module named 'dotenv'

Traceback (most recent call last):
Traceback (most recent call last):
  File "C:\Codes\GitHub\alldesign_website\backend\manage.py", line 23, in <module>
  File "C:\Codes\GitHub\alldesign_website\backend\manage.py", line 23, in <module>
        main()main()

  File "C:\Codes\GitHub\alldesign_website\backend\manage.py", line 19, in main
  File "C:\Codes\GitHub\alldesign_website\backend\manage.py", line 19, in main
        execute_from_command_line(sys.argv)execute_from_command_line(sys.argv)

  File "C:\Users\DeogSeon\AppData\Local\Packages\PythonSoftwareFoundation.Python.3.12_qbz5n2kfra8p0\LocalCache\local-packages\Python312\site-packages\django\core\management\__init__.py", line 442, in execute_from_command_line
  File "C:\Users\DeogSeon\AppData\Local\Packages\PythonSoftwareFoundation.Python.3.12_qbz5n2kfra8p0\LocalCache\local-packages\Python312\site-packages\django\core\management\__init__.py", line 442, in execute_from_command_line
        utility.execute()utility.execute()

  File "C:\Users\DeogSeon\AppData\Local\Packages\PythonSoftwareFoundation.Python.3.12_qbz5n2kfra8p0\LocalCache\local-packages\Python312\site-packages\django\core\management\__init__.py", line 436, in execute
  File "C:\Users\DeogSeon\AppData\Local\Packages\PythonSoftwareFoundation.Python.3.12_qbz5n2kfra8p0\LocalCache\local-packages\Python312\site-packages\django\core\management\__init__.py", line 436, in execute
        self.fetch_command(subcommand).run_from_argv(self.argv)self.fetch_command(subcommand).run_from_argv(self.argv)

  File "C:\Users\DeogSeon\AppData\Local\Packages\PythonSoftwareFoundation.Python.3.12_qbz5n2kfra8p0\LocalCache\local-packages\Python312\site-packages\django\core\management\base.py", line 408, in run_from_argv
  File "C:\Users\DeogSeon\AppData\Local\Packages\PythonSoftwareFoundation.Python.3.12_qbz5n2kfra8p0\LocalCache\local-packages\Python312\site-packages\django\core\management\base.py", line 408, in run_from_argv
        parser = self.create_parser(argv[0], argv[1])parser = self.create_parser(argv[0], argv[1])

                          ^^^^^^^^^^^^^^^^^^^^^^^^^^^^^^^^^^^^^^^^^^^^^^^^^^^^^^^^^^^^^^^^^^^^^^^^

  File "C:\Users\DeogSeon\AppData\Local\Packages\PythonSoftwareFoundation.Python.3.12_qbz5n2kfra8p0\LocalCache\local-packages\Python312\site-packages\django\core\management\base.py", line 371, in create_parser
  File "C:\Users\DeogSeon\AppData\Local\Packages\PythonSoftwareFoundation.Python.3.12_qbz5n2kfra8p0\LocalCache\local-packages\Python312\site-packages\django\core\management\base.py", line 371, in create_parser
        self.add_arguments(parser)self.add_arguments(parser)

  File "C:\Users\DeogSeon\AppData\Local\Packages\PythonSoftwareFoundation.Python.3.12_qbz5n2kfra8p0\LocalCache\local-packages\Python312\site-packages\django\core\management\commands\migrate.py", line 45, in add_arguments
  File "C:\Users\DeogSeon\AppData\Local\Packages\PythonSoftwareFoundation.Python.3.12_qbz5n2kfra8p0\LocalCache\local-packages\Python312\site-packages\django\core\management\commands\migrate.py", line 45, in add_arguments
        choices=tuple(connections),choices=tuple(connections),

                        ^^^^^^^^^^^^^^^^^^^^^^^^^^^^^^^^^^^^

  File "C:\Users\DeogSeon\AppData\Local\Packages\PythonSoftwareFoundation.Python.3.12_qbz5n2kfra8p0\LocalCache\local-packages\Python312\site-packages\django\utils\connection.py", line 73, in __iter__
  File "C:\Users\DeogSeon\AppData\Local\Packages\PythonSoftwareFoundation.Python.3.12_qbz5n2kfra8p0\LocalCache\local-packages\Python312\site-packages\django\utils\connection.py", line 73, in __iter__
        return iter(self.settings)return iter(self.settings)

                                ^^^^^^^^^^^^^^^^^^^^^^^^^^

  File "C:\Users\DeogSeon\AppData\Local\Packages\PythonSoftwareFoundation.Python.3.12_qbz5n2kfra8p0\LocalCache\local-packages\Python312\site-packages\django\utils\functional.py", line 47, in __get__
  File "C:\Users\DeogSeon\AppData\Local\Packages\PythonSoftwareFoundation.Python.3.12_qbz5n2kfra8p0\LocalCache\local-packages\Python312\site-packages\django\utils\functional.py", line 47, in __get__
        res = instance.__dict__[self.name] = self.func(instance)res = instance.__dict__[self.name] = self.func(instance)

                                                                                  ^^^^^^^^^^^^^^^^^^^^^^^^^^^^^^^^^^^^^^

  File "C:\Users\DeogSeon\AppData\Local\Packages\PythonSoftwareFoundation.Python.3.12_qbz5n2kfra8p0\LocalCache\local-packages\Python312\site-packages\django\utils\connection.py", line 45, in settings
  File "C:\Users\DeogSeon\AppData\Local\Packages\PythonSoftwareFoundation.Python.3.12_qbz5n2kfra8p0\LocalCache\local-packages\Python312\site-packages\django\utils\connection.py", line 45, in settings
        self._settings = self.configure_settings(self._settings)self._settings = self.configure_settings(self._settings)

                                          ^^^^^^^^^^^^^^^^^^^^^^^^^^^^^^^^^^^^^^^^^^^^^^^^^^^^^^^^^^^^^^^^^^^^^^^^^^^^^^

  File "C:\Users\DeogSeon\AppData\Local\Packages\PythonSoftwareFoundation.Python.3.12_qbz5n2kfra8p0\LocalCache\local-packages\Python312\site-packages\django\db\utils.py", line 148, in configure_settings
  File "C:\Users\DeogSeon\AppData\Local\Packages\PythonSoftwareFoundation.Python.3.12_qbz5n2kfra8p0\LocalCache\local-packages\Python312\site-packages\django\db\utils.py", line 148, in configure_settings
        databases = super().configure_settings(databases)databases = super().configure_settings(databases)

                                ^^^^^^^^^^^^^^^^^^^^^^^^^^^^^^^^^^^^^^^^^^^^^^^^^^^^^^^^^^^^^^^^^^^^^^^^^^

  File "C:\Users\DeogSeon\AppData\Local\Packages\PythonSoftwareFoundation.Python.3.12_qbz5n2kfra8p0\LocalCache\local-packages\Python312\site-packages\django\utils\connection.py", line 50, in configure_settings
  File "C:\Users\DeogSeon\AppData\Local\Packages\PythonSoftwareFoundation.Python.3.12_qbz5n2kfra8p0\LocalCache\local-packages\Python312\site-packages\django\utils\connection.py", line 50, in configure_settings
        settings = getattr(django_settings, self.settings_name)settings = getattr(django_settings, self.settings_name)

                              ^^^^^^^^^^^^^^^^^^^^^^^^^^^^^^^^^^^^^^^^^^^^^^^^^^^^^^^^^^^^^^^^^^^^^^^^^^^^^^^^^^^^^^^^

  File "C:\Users\DeogSeon\AppData\Local\Packages\PythonSoftwareFoundation.Python.3.12_qbz5n2kfra8p0\LocalCache\local-packages\Python312\site-packages\django\conf\__init__.py", line 81, in __getattr__
  File "C:\Users\DeogSeon\AppData\Local\Packages\PythonSoftwareFoundation.Python.3.12_qbz5n2kfra8p0\LocalCache\local-packages\Python312\site-packages\django\conf\__init__.py", line 81, in __getattr__
        self._setup(name)self._setup(name)

  File "C:\Users\DeogSeon\AppData\Local\Packages\PythonSoftwareFoundation.Python.3.12_qbz5n2kfra8p0\LocalCache\local-packages\Python312\site-packages\django\conf\__init__.py", line 68, in _setup
  File "C:\Users\DeogSeon\AppData\Local\Packages\PythonSoftwareFoundation.Python.3.12_qbz5n2kfra8p0\LocalCache\local-packages\Python312\site-packages\django\conf\__init__.py", line 68, in _setup
        self._wrapped = Settings(settings_module)self._wrapped = Settings(settings_module)

                                        ^^^^^^^^^^^^^^^^^^^^^^^^^^^^^^^^^^^^^^^^^^^^^^^^^^

  File "C:\Users\DeogSeon\AppData\Local\Packages\PythonSoftwareFoundation.Python.3.12_qbz5n2kfra8p0\LocalCache\local-packages\Python312\site-packages\django\conf\__init__.py", line 166, in __init__
  File "C:\Users\DeogSeon\AppData\Local\Packages\PythonSoftwareFoundation.Python.3.12_qbz5n2kfra8p0\LocalCache\local-packages\Python312\site-packages\django\conf\__init__.py", line 166, in __init__
        mod = importlib.import_module(self.SETTINGS_MODULE)mod = importlib.import_module(self.SETTINGS_MODULE)

                    ^^^^^^^^^^^^^^^^^^^^^^^^^^^^^^^^^^^^^^^^^^^^^^^^^^^^^^^^^^^^^^^^^^^^^^^^^^^^^^^^^^^^^^^^^^

  File "C:\Program Files\WindowsApps\PythonSoftwareFoundation.Python.3.12_3.12.2800.0_x64__qbz5n2kfra8p0\Lib\importlib\__init__.py", line 90, in import_module
  File "C:\Program Files\WindowsApps\PythonSoftwareFoundation.Python.3.12_3.12.2800.0_x64__qbz5n2kfra8p0\Lib\importlib\__init__.py", line 90, in import_module
        return _bootstrap._gcd_import(name[level:], package, level)return _bootstrap._gcd_import(name[level:], package, level)

                      ^^^^^^^^^^^^^^^^^^^^^^^^^^^^^^^^^^^^^^^^^^^^^^^^^^^^^^^^^^^^^^^^^^^^^^^^^^^^^^^^^^^^^^^^^^^^^^^^^^^^^^^^

  File "<frozen importlib._bootstrap>", line 1387, in _gcd_import
  File "<frozen importlib._bootstrap>", line 1387, in _gcd_import
  File "<frozen importlib._bootstrap>", line 1360, in _find_and_load
  File "<frozen importlib._bootstrap>", line 1360, in _find_and_load
  File "<frozen importlib._bootstrap>", line 1331, in _find_and_load_unlocked
  File "<frozen importlib._bootstrap>", line 1331, in _find_and_load_unlocked
  File "<frozen importlib._bootstrap>", line 935, in _load_unlocked
  File "<frozen importlib._bootstrap>", line 935, in _load_unlocked
  File "<frozen importlib._bootstrap_external>", line 999, in exec_module
  File "<frozen importlib._bootstrap_external>", line 999, in exec_module
  File "<frozen importlib._bootstrap>", line 488, in _call_with_frames_removed
  File "<frozen importlib._bootstrap>", line 488, in _call_with_frames_removed
  File "C:\Codes\GitHub\alldesign_website\backend\backend\settings.py", line 4, in <module>
  File "C:\Codes\GitHub\alldesign_website\backend\backend\settings.py", line 4, in <module>
        import pymysqlimport pymysql

ModuleNotFoundErrorModuleNotFoundError: : No module named 'pymysql'No module named 'pymysql'

order@alldesignkhv.ru (147369fgH+)
Traceback (most recent call last):
Traceback (most recent call last):
  File "C:\Codes\GitHub\alldesign_website\backend\manage.py", line 23, in <module>
  File "C:\Codes\GitHub\alldesign_website\backend\manage.py", line 23, in <module>
        main()main()

  File "C:\Codes\GitHub\alldesign_website\backend\manage.py", line 19, in main
  File "C:\Codes\GitHub\alldesign_website\backend\manage.py", line 19, in main
        execute_from_command_line(sys.argv)execute_from_command_line(sys.argv)

  File "C:\Users\DeogSeon\AppData\Local\Packages\PythonSoftwareFoundation.Python.3.12_qbz5n2kfra8p0\LocalCache\local-packages\Python312\site-packages\django\core\management\__init__.py", line 442, in execute_from_command_line
  File "C:\Users\DeogSeon\AppData\Local\Packages\PythonSoftwareFoundation.Python.3.12_qbz5n2kfra8p0\LocalCache\local-packages\Python312\site-packages\django\core\management\__init__.py", line 442, in execute_from_command_line
        utility.execute()utility.execute()

  File "C:\Users\DeogSeon\AppData\Local\Packages\PythonSoftwareFoundation.Python.3.12_qbz5n2kfra8p0\LocalCache\local-packages\Python312\site-packages\django\core\management\__init__.py", line 416, in execute
  File "C:\Users\DeogSeon\AppData\Local\Packages\PythonSoftwareFoundation.Python.3.12_qbz5n2kfra8p0\LocalCache\local-packages\Python312\site-packages\django\core\management\__init__.py", line 416, in execute
        django.setup()django.setup()

  File "C:\Users\DeogSeon\AppData\Local\Packages\PythonSoftwareFoundation.Python.3.12_qbz5n2kfra8p0\LocalCache\local-packages\Python312\site-packages\django\__init__.py", line 24, in setup
  File "C:\Users\DeogSeon\AppData\Local\Packages\PythonSoftwareFoundation.Python.3.12_qbz5n2kfra8p0\LocalCache\local-packages\Python312\site-packages\django\__init__.py", line 24, in setup
        apps.populate(settings.INSTALLED_APPS)apps.populate(settings.INSTALLED_APPS)

  File "C:\Users\DeogSeon\AppData\Local\Packages\PythonSoftwareFoundation.Python.3.12_qbz5n2kfra8p0\LocalCache\local-packages\Python312\site-packages\django\apps\registry.py", line 91, in populate
  File "C:\Users\DeogSeon\AppData\Local\Packages\PythonSoftwareFoundation.Python.3.12_qbz5n2kfra8p0\LocalCache\local-packages\Python312\site-packages\django\apps\registry.py", line 91, in populate
        app_config = AppConfig.create(entry)app_config = AppConfig.create(entry)

                                  ^^^^^^^^^^^^^^^^^^^^^^^^^^^^^^^^^^^^^^^^^^^^^^

  File "C:\Users\DeogSeon\AppData\Local\Packages\PythonSoftwareFoundation.Python.3.12_qbz5n2kfra8p0\LocalCache\local-packages\Python312\site-packages\django\apps\config.py", line 193, in create
  File "C:\Users\DeogSeon\AppData\Local\Packages\PythonSoftwareFoundation.Python.3.12_qbz5n2kfra8p0\LocalCache\local-packages\Python312\site-packages\django\apps\config.py", line 193, in create
        import_module(entry)import_module(entry)

  File "C:\Program Files\WindowsApps\PythonSoftwareFoundation.Python.3.12_3.12.2800.0_x64__qbz5n2kfra8p0\Lib\importlib\__init__.py", line 90, in import_module
  File "C:\Program Files\WindowsApps\PythonSoftwareFoundation.Python.3.12_3.12.2800.0_x64__qbz5n2kfra8p0\Lib\importlib\__init__.py", line 90, in import_module
        return _bootstrap._gcd_import(name[level:], package, level)return _bootstrap._gcd_import(name[level:], package, level)

                      ^^^^^^^^^^^^^^^^^^^^^^^^^^^^^^^^^^^^^^^^^^^^^^^^^^^^^^^^^^^^^^^^^^^^^^^^^^^^^^^^^^^^^^^^^^^^^^^^^^^^^^^^

  File "<frozen importlib._bootstrap>", line 1387, in _gcd_import
  File "<frozen importlib._bootstrap>", line 1387, in _gcd_import
  File "<frozen importlib._bootstrap>", line 1360, in _find_and_load
  File "<frozen importlib._bootstrap>", line 1360, in _find_and_load
  File "<frozen importlib._bootstrap>", line 1324, in _find_and_load_unlocked
  File "<frozen importlib._bootstrap>", line 1324, in _find_and_load_unlocked
ModuleNotFoundErrorModuleNotFoundError: : No module named 'admin_interface'No module named 'admin_interface'

order@alldesignkhv.ru (147369fgH+)
Traceback (most recent call last):
Traceback (most recent call last):
  File "C:\Codes\GitHub\alldesign_website\backend\manage.py", line 23, in <module>
  File "C:\Codes\GitHub\alldesign_website\backend\manage.py", line 23, in <module>
        main()main()

  File "C:\Codes\GitHub\alldesign_website\backend\manage.py", line 19, in main
  File "C:\Codes\GitHub\alldesign_website\backend\manage.py", line 19, in main
        execute_from_command_line(sys.argv)execute_from_command_line(sys.argv)

  File "C:\Users\DeogSeon\AppData\Local\Packages\PythonSoftwareFoundation.Python.3.12_qbz5n2kfra8p0\LocalCache\local-packages\Python312\site-packages\django\core\management\__init__.py", line 442, in execute_from_command_line
  File "C:\Users\DeogSeon\AppData\Local\Packages\PythonSoftwareFoundation.Python.3.12_qbz5n2kfra8p0\LocalCache\local-packages\Python312\site-packages\django\core\management\__init__.py", line 442, in execute_from_command_line
        utility.execute()utility.execute()

  File "C:\Users\DeogSeon\AppData\Local\Packages\PythonSoftwareFoundation.Python.3.12_qbz5n2kfra8p0\LocalCache\local-packages\Python312\site-packages\django\core\management\__init__.py", line 416, in execute
  File "C:\Users\DeogSeon\AppData\Local\Packages\PythonSoftwareFoundation.Python.3.12_qbz5n2kfra8p0\LocalCache\local-packages\Python312\site-packages\django\core\management\__init__.py", line 416, in execute
        django.setup()django.setup()

  File "C:\Users\DeogSeon\AppData\Local\Packages\PythonSoftwareFoundation.Python.3.12_qbz5n2kfra8p0\LocalCache\local-packages\Python312\site-packages\django\__init__.py", line 24, in setup
  File "C:\Users\DeogSeon\AppData\Local\Packages\PythonSoftwareFoundation.Python.3.12_qbz5n2kfra8p0\LocalCache\local-packages\Python312\site-packages\django\__init__.py", line 24, in setup
        apps.populate(settings.INSTALLED_APPS)apps.populate(settings.INSTALLED_APPS)

  File "C:\Users\DeogSeon\AppData\Local\Packages\PythonSoftwareFoundation.Python.3.12_qbz5n2kfra8p0\LocalCache\local-packages\Python312\site-packages\django\apps\registry.py", line 91, in populate
  File "C:\Users\DeogSeon\AppData\Local\Packages\PythonSoftwareFoundation.Python.3.12_qbz5n2kfra8p0\LocalCache\local-packages\Python312\site-packages\django\apps\registry.py", line 91, in populate
        app_config = AppConfig.create(entry)app_config = AppConfig.create(entry)

                                  ^^^^^^^^^^^^^^^^^^^^^^^^^^^^^^^^^^^^^^^^^^^^^^

  File "C:\Users\DeogSeon\AppData\Local\Packages\PythonSoftwareFoundation.Python.3.12_qbz5n2kfra8p0\LocalCache\local-packages\Python312\site-packages\django\apps\config.py", line 193, in create
  File "C:\Users\DeogSeon\AppData\Local\Packages\PythonSoftwareFoundation.Python.3.12_qbz5n2kfra8p0\LocalCache\local-packages\Python312\site-packages\django\apps\config.py", line 193, in create
        import_module(entry)import_module(entry)

  File "C:\Program Files\WindowsApps\PythonSoftwareFoundation.Python.3.12_3.12.2800.0_x64__qbz5n2kfra8p0\Lib\importlib\__init__.py", line 90, in import_module
  File "C:\Program Files\WindowsApps\PythonSoftwareFoundation.Python.3.12_3.12.2800.0_x64__qbz5n2kfra8p0\Lib\importlib\__init__.py", line 90, in import_module
        return _bootstrap._gcd_import(name[level:], package, level)return _bootstrap._gcd_import(name[level:], package, level)

                      ^^^^^^^^^^^^^^^^^^^^^^^^^^^^^^^^^^^^^^^^^^^^^^^^^^^^^^^^^^^^^^^^^^^^^^^^^^^^^^^^^^^^^^^^^^^^^^^^^^^^^^^^

  File "<frozen importlib._bootstrap>", line 1387, in _gcd_import
  File "<frozen importlib._bootstrap>", line 1387, in _gcd_import
  File "<frozen importlib._bootstrap>", line 1360, in _find_and_load
  File "<frozen importlib._bootstrap>", line 1360, in _find_and_load
  File "<frozen importlib._bootstrap>", line 1324, in _find_and_load_unlocked
  File "<frozen importlib._bootstrap>", line 1324, in _find_and_load_unlocked
ModuleNotFoundErrorModuleNotFoundError: : No module named 'rest_framework'No module named 'rest_framework'

